Workbook
Name Approval_ApproversSL4_SL5: #REF!
Name Approval_ApproversSL4_SL5: #REF!
Name Approval_ApproversSL4_SL5: '[1]Strategy Attributes'!#REF!
Name AttributeRange: #REF!
Name AttributeRange: #REF!
Name AttributeRange: [1]!Input_Requirements[[#All],[Attribute]]
Name FlowType_Step1: Transform_Logic_Prod_LEGACY!$M$13
Name HeaderRange: 'Dev Fields'!$A$1:$L$1
Name HeaderRange: 'Prod Fields'!$A$1:$N$1
Name HeaderRange: 'SBA Fields'!$A$1:$G$1
Name Prod_WorkType: Transform_Logic_Prod_LEGACY!$M$20
Name VAL_DeferedRisk: #REF!
Name VAL_DeferedRisk: #REF!
Name VAL_DeferedRisk: VAL_RiskLevel[]
Name VAL_DefferedRisk: #REF!
Name VAL_DefferedRisk: #REF!
Name VAL_DefferedRisk: VAL_RiskLevel[]
Name VAL_ValueFramework: #REF!
Name VAL_ValueFramework: #REF!
Name VAL_ValueFramework: VAL_ValueFramework1[]
Name WAVE_InScope: #REF!
Name WR53_DemandSubType: Transform_Logic_Prod_LEGACY!$M$50

Sheet ReadME
A1: Worksheet Name | B1: Usage
A2: Config_Tech_Enabled | B2: This is where we should store all of our configuration requirements for Tech_enabled Value Bundles and their respective epics. We will expand to the financial lines as well when it is time. Goal is to eventually also include the Strategic Program Configuration Requirements in the same tab

Sheet Open Stakeholder Questions
A1: Topic | B1: Question | C1: Owner | D1: Answer | E1: Status | F1: Date Answered
A2: Missing Attributes in Work Structure | B2: There is no home for the following attributes from Prod in the work hierarchy. Should they be created so we don't lose the data: -L1 Net Recurring Benefits ($, annualized)-P&L/Hard -L2 Net Recurring Benefits ($, annualized)-P&L/Hard -Special Projects -L1 One-time Benefit ($)-Total -Initial Net Recurring Benefits ($, annualized)-P&L/Hard -NRB (Exit Rate) 2028 (Latest Estimate) -Enterprise Strategic Initiative (ESI) -Azure Subscription Group -MS Azure Usage Size | C2: Bibhusha | E2: Open
A3: Flow Type | B3: NRB (both exit rate and the L1 field) are used as a mechanism for classifying the flow type; however, the exit rate is allowed to be massively negative. How would we want to treat this in the estimated value range that is consolidated from the 3 fields? Is it Low because it's under $10M, or do we consider this an error in understanding, and so we should take the absolute value of the number | C3: Jodi | D3: negative values are considered low. We should not do absolute values | E3: Addressed in Code
A4: Flow Type | B4: Is Flow Type to remain null if it is Business Only Demand? | C4: Jodi | D4: Yes | E4: Addressed in Code
A5: Flow Type | B5: If Initiative is Biz w/ tech but is $<10M and has a t-size of L or XL then what should the flow type be? | C5: Jodi | D5: Addressed in the flow logic now. | E5: Addressed in Code
A6: Mismatch - Domain vs Home Portfolio or Domain | B6: "Domain" and "Domain or Home Portfolio" do not match always (~120 records). Which field is most appropriate to place the demand. Note this is likely most relevant for business demand. Here are the unique options that happened: | C6: Jodi and Bibhusha | D6: Use Domain, not Home Domain or Portfolio | E6: Answered
A7: Work Hierarchy | B7: In the work hierarchy, are we keeping both "C-" and "P&C-" tree leaves? Does C represent confidential and P&C represents ultra-confidential? | D7: Yes, C represents confidential and P&C represents ultra-confidential | E7: Addressed in Code
A8: Attributes | B8: Why are both Demand SubType and Risk SubType needed? They are the same dropdown options. | D8: Demand Subtype is no longer used in the new design. Risk Subtype is used instead. And this applies only to work going under the Tech Enabled Intake Work Type (aka Discretionary/Non- Discretionary Demand Type) | E8: Open
A9: Visibility | B9: Can WR56 be made available as a column? | C9: Bibhusha | D9: Was made available as a column | E9: Answered | F9: 46161
A10: Execution Type | B10: Should I be filtering out this "Initiative Milestones & Risks"? It might be a placeholder epic and not really be valuable but it's hard to tell | C10: TJ | D10: Yes, filter out the execution type initiative milestone & Risks but do not remove its children milestones and tasks | E10: Answered
A11: Impacted Portfolios | B11: In SBA, Impacted Portfolios appears inconsistent with the columns that say "Impact X Portfolio".. Should we just consolidate the Yes's into a new column and ignore "Impacted Portfolios" column | D11: Technically, "Impacts X Portfolio" aligns 1:1 with the final Prod attributes so these should be accurately filled. Can you please follow up with business takeholders on the discrepancy in data entered? Please confirm with Christina Dunphy & Eryn Walter for DRIVE bundles. Emilee James & Jodi McDowell for D&T value bundles. [C Dunphy] - The impacted portfolios are filled in as the information is obtained. We do not have lifecycle steps in SBA so we cannot make every future required field, required in SBA, as they wouldn't be able to save the data upon creation. This data will continue to be populated in SBA as they work their way through L2 | E11: Answered
A12: Missing data in SBA | B12: The following attributes in SBA are not filled (all null). Can we just exclude them from the migration scripts? Note the ones that are marked as issues need to be resolved ASAP. See table in worksheet "SBA Empty attributes" | C12: Christina | D12: Can you remove the Epic fields from that list because Epics are migrated from Prod, not from SBA. Outside those, if required fields are not filled out, then Christina Dunphy & Eryn Walter are the contacts for DRIVE. Emilee James & Jodi McDowell are the contacts for D&T. | E12: Open
A13: New Attribute SBA | B13: Can we add a mapping attribute in SBA for the legacy Sequence ID? | C13: Cynthia | D13: Created | E13: Answered
A14: Work Hierarchy | B14: What do you want to do about existing Freight demand | C14: Christina | D14: TJ thinks we might be eliminating these work items | E14: Open
A15: Attributes | B15: In Dev, STR136 has an extra space at the end of the attribute name. Please delete this space | C15: TJ-->Jill | E15: Open
A16: SBA Cleanup | B16: When will the cleanup be done in SBA given the PPL+1 for existing data seems incorrect | C16: TJ | E16: Open
A17: Logbook Migration | B17: Do we have a view of the attributes and their validation options in logbook? What are the codes to migrate? | C17: TJ | D17: Asnwered in email on 6/1. Technical IDs translation will be done directly by planview. TJ to see if we need another attribute custom made for risk owner | E17: Open
A18: Prod Cleanup | B18: What do we do about the orphaned Epics in the work structure | C18: TJ | D18: Orphaned epics should not occur and will be handled via data quality cleanup/triage rather than adding migration logic to support them. Own communications + next steps for orphaned epics post-cleanup (publish list of items NOT migrated + exceptions) | E18: Open | F18: 46162
A19: Removal of Initiative milestones & Risks containers | B19: In the work structure, we will not migrate Execution Type where "Initiative Milestones & Risks", regardless of the demand type being business only or Biz w/ Tech. | C19: TJ | D19: For the milestone containers, we need the milestones but not the containers itself. Max will handle the removal in the final migration step | E19: Answered
A20: Orphaned Epics | B20: Any Biz w/ Tech Epic without a parent Initiative will not be migrated | C20: TJ | D20: Orphaned epics should not occur and will be handled via data quality cleanup/triage rather than adding migration logic to support them. Own communications + next steps for orphaned epics post-cleanup (publish list of items NOT migrated + exceptions) | E20: Open | F20: 46162
A21: SBA Replacement Attribute format - Strategy | B21: I don't think "Previous Strategy Seq. ID" (fdx_a_prev_str_seqid) is meant to be used, right? This is in the strategy structure which doesn't help us | C21: TJ | D21: Removed | E21: Answered
A22: SBA Replacement Attribute format - Work | B22: Can you rename the field "Previous Work Seq. ID" to "Previous Seq_ID" (fdx_a_prev_wrk_seqid). Then afterwards, can you fill it with a few examples. Please let me know if there's a scenario where there are multiple and how that format will be added. Also give guidance on how to treat the multiple… Do we wish to combine all the items underneath this one item? | C22: TJ | D22: Modified the name | E22: Answered
A23: Milestones/Tasks | B23: Do we understand the requirement right? All tasks / milestones will be converted into milestones with no duration and no start date. This applies to all items, business only, LE/LM, biz w/ tech epic. Also what do we want to apply for execution types on the PPL+2 items that are not SBA and not Epics | C23: TJ | D23: Max misunderstood this. It's not a thing | E23: Answered
A24: Agility Sync Attributes | B24: What does the transformation table need to look like for flipping (IN AGILITY) the previous work ID with the new one from Dev | C24: Steven | E24: Open
A25: SBA Extract | B25: 1) Did you pull the right column for its parent Sequence ID? It shouldn't be going to its Value bundle, but rather its execution package 2) Can you share with us the methodology for filtering out the PPL+2 items? 3) If Epics are at the same level as the tasks, wouldn't it be safer for us to just do a main extract of everything at PPL+ 0, then PPL+1 then PPL+2 rather than breaking out the PPL+2 into Epics vs tasks | C25: Bert | E25: Open
A26: Show on Roadmap | B26: Do we want to set "Show on Roadmap" to "Show on Strategy & Project" for all Epics that came from prod? | C26: TJ | D26: Yes | E26: Answered | F26: 46174

Sheet Config_Strategic_Program
A1: Source Tab | B1: Lifecycle Stage | C1: Source Demand Type | D1: Target Demand Type | E1: Target Entity | F1: Target Field Name | G1: Required | H1: Source FDXSANDBOXA ID | I1: Target DEV SB ID | J1: Type | K1: Selection Type | L1: Has Dropdown | M1: Entity_Flag_Manual_Review
A2: L1 - Strategy Def | B2: L1 | F2: Name | G2: Required | H2: strat_name | I2: strat_name | J2: Field | L2: No | M2: YES
A3: L1 - Strategy Def | B3: L1 | F3: Strategic Parent | G3: Required | H3: StratRoot | I3: StratRoot | J3: Strategic Hierarchy | L3: No | M3: YES
A4: L1 - Strategy Def | B4: L1 | F4: Brief Demand Description | G4: Required | H4: strat_descr | I4: strat_descr | J4: Field | L4: No | M4: YES
A5: L1 - Strategy Def | B5: L1 | F5: Target Start | G5: Optional | H5: strat_target_start | I5: strat_target_start | J5: Field | L5: No | M5: YES
A6: L1 - Strategy Def | B6: L1 | F6: Target Finish | G6: Optional | H6: strat_target_finish | I6: strat_target_finish | J6: Field | L6: No | M6: YES
A7: L1 - Strategy Def | B7: L1 | F7: Program Owner | G7: Required | H7: 178308 | I7: 190983 | J7: Field | K7: Single | L7: Yes | M7: YES
A8: L1 - Strategy Def | B8: L1 | F8: Program Manager | G8: Required | H8: 178309 | I8: 190984 | J8: Field | K8: Multi | L8: Yes | M8: YES
A9: L1 - Strategy Def | B9: L1 | F9: D&T Captain | G9: Required | H9: 178311 | I9: 190985 | J9: Field | K9: Single | L9: Yes | M9: YES
A10: L1 - Strategy Def | B10: L1 | F10: ESPM | G10: Required | H10: 178312 | I10: 190986 | J10: Field | K10: Multi | L10: Yes | M10: YES
A11: L1 - Strategy Def | B11: L1 | F11: Business Finance | G11: Required | H11: 178340 | I11: 190987 | J11: Field | K11: Multi | L11: Yes | M11: YES
A12: L1 - Strategy Def | B12: L1 | F12: Architecture Program Manager | G12: Optional | H12: 178310 | I12: 190988 | J12: Field | K12: Single | L12: Yes | M12: YES
A13: L1 - Strategy Def | B13: L1 | F13: TO Finance | G13: Required | H13: 3399 | I13: 3399 | J13: Field | K13: Single | L13: Yes | M13: YES
A14: L1 - Strategy Def | B14: L1 | F14: TO Approver | G14: Required | H14: 178339 | I14: 190989 | J14: Field | K14: Multi | L14: Yes | M14: YES
A15: L1 - Strategy Def | B15: L1 | F15: EPM | G15: Required | H15: 4181 | I15: 4181 | J15: Field | K15: Multi | L15: Yes | M15: YES
A16: L1 - Strategy Def | B16: L1 | F16: Expected Business Outcome | G16: Optional | H16: fdx_biz_out_strat | I16: fdx_biz_out_strat | J16: Field | L16: No | M16: YES
A17: L1 - Strategy Def | B17: L1 | F17: Initial Net Recurring Benefits ($, annualized)-P&L/Hard | G17: Optional | H17: fdx_l1_nrb_hard | I17: fdx_l1_nrb_hard | J17: Field | L17: No | M17: YES
A18: L1 - Strategy Def | B18: L1 | F18: Initial Net Recurring Benefits ($, annualized)-Soft | G18: Optional | H18: fdx_l1_nrb_soft | I18: fdx_l1_nrb_soft | J18: Field | L18: No | M18: YES
A19: L1 - Strategy Def | B19: L1 | F19: Initial Net Recurring Benefits ($, annualized)-Total | G19: Optional | H19: 1044 | I19: 1044 | J19: Calculated | L19: No | M19: YES
A20: L1 - Strategy Def | B20: L1 | F20: Initial One-time Benefit ($) | G20: Optional | H20: fdx_l1_otb_total | I20: fdx_l1_otb_total | J20: Field | L20: No | M20: YES
A21: L1 - Strategy Def | B21: L1 | F21: Key Assumptions Made in Quantifying Impact | G21: Optional | H21: fdx_calc_explan | I21: fdx_calc_explan | J21: Field | L21: No | M21: YES
A22: L1 - Strategy Def | B22: L1 | F22: Primary Type of Value | G22: Required | H22: Str119 | I22: Str119 | J22: Alt. Struct | K22: Single | L22: Yes | M22: YES
A23: L1 - Strategy Def | B23: L1 | F23: Does this Program impact Customer Experience? | G23: Optional | H23: Str136 | I23: Str32 | J23: Alt. Struct | K23: Single | L23: Yes | M23: YES
A24: L1 - Strategy Def | B24: L1 | F24: If yes, indicate level of Customer Experience impact | G24: Optional | H24: Wbs125 | I24: Wbs57 | J24: Alt. Struct | K24: Single | L24: Yes | M24: YES
A25: L1 - Strategy Def | B25: L1 | F25: Does this Program impact Service? | G25: Optional | H25: Str137 | I25: Str48 | J25: Alt. Struct | K25: Single | L25: Yes | M25: YES
A26: L1 - Strategy Def | B26: L1 | F26: If yes, indicate level of Service impact | G26: Optional | H26: Wbs126 | I26: Wbs59 | J26: Alt. Struct | K26: Single | L26: Yes | M26: YES
A27: L1 - Strategy Def | B27: L1 | F27: OKRs: | G27: - | H27: - | I27: - | J27: static text | L27: No | M27: YES
A28: L1 - Strategy Def | B28: L1 | F28: Enterprise KPI | G28: Required | H28: Str134 | I28: Str134 | J28: Alt. Struct | K28: Multi | L28: Yes | M28: YES
A29: L1 - Strategy Def | B29: L1 | F29: Program Dependencies | G29: - | H29: - | I29: - | J29: Dependency container | L29: No | M29: YES
A30: L1 - Strategy Def | B30: L1 | F30: Commercial Dependencies | G30: Optional | H30: Str138 | I30: Str49 | J30: Alt. Struct | K30: Multi | L30: Yes | M30: YES
A31: L1 - Strategy Def | B31: L1 | F31: SL2 Business Finance Approval | G31: Required | H31: Str140 | I31: Str52 | J31: Alt. Struct | K31: Single | L31: Yes | M31: YES
A32: L1 - Strategy Def | B32: L1 | F32: SL2 Business Finance Approval Notes | G32: Required | H32: fdx_bfin_appv_notes | I32: fdx_bfin_appv_notes | J32: Field | L32: No | M32: YES
A33: L1 - Strategy Def | B33: L1 | F33: SL2 Program Owner Approval | G33: Required | H33: Str141 | I33: Str53 | J33: Alt. Struct | K33: Single | L33: Yes | M33: YES
A34: L1 - Strategy Def | B34: L1 | F34: SL2 Program Owner Approval Notes | G34: Required | H34: fdx_pgo_appv_notes | I34: fdx_pgo_appv_notes | J34: Field | L34: No | M34: YES
A35: L1 - Strategy Def | B35: L1 | F35: SL2 ESPM Review | G35: Required | H35: Str142 | I35: Str54 | J35: Alt. Struct | K35: Single | L35: Yes | M35: YES
A36: L1 - Strategy Def | B36: L1 | F36: SL2 ESPM Review Notes | G36: Required | H36: fdx_espm_rev_notes | I36: fdx_espm_rev_notes | J36: Field | L36: No | M36: YES
A37: L1 - Strategy Def | B37: L1 | F37: SL2 TO Approval | G37: Required | H37: Str143 | I37: Str55 | J37: Alt. Struct | K37: Single | L37: Yes | M37: YES
A38: L1 - Strategy Def | B38: L1 | F38: SL2 TO Approval Notes | G38: Required | H38: fdx_to_appv_notes | I38: fdx_to_appv_notes | J38: Field | L38: No | M38: YES
A39: L1 - Strategy Def | B39: L1 | F39: Status | G39: Read Only | H39: SpsStatus | I39: SpsStatus | J39: Alt. Struct | K39: Single | L39: Yes | M39: YES
A40: L1 - Strategy Def | B40: L1 | F40: Program Type | H40: Str144 | I40: Str61 | J40: Alt. Struct | K40: Single | L40: Yes | M40: YES
...

Sheet Work Hierarchy
A1: Work Structure
A3: Level Names
A4: Level | B4: Name | E4: Comments and Design Decisions
A5: 1 | B5: Lvl1:
A6: 2 | B6: Lvl2:
A7: 3 | B7: Lvl3:
A8: 4 | B8: Lvl4:
A9: 5 | B9: Lvl5:
A10: 6 | B10: >
A11: 7 | B11: >>
A12: 8 | B12: >>>
A15: Structure
A16: Lvl1: | B16: Column1 | C16: Lvl2: | D16: Lvl3: | E16: Column2 | F16: Lvl4: | G16: Column3 | H16: Column4 | I16: Consolidated Name | J16: Level | K16: Normalized Name | L16: Normalized Sequence ID
A17: FedEx (PlanRoot) | I17: =IF(A17<>"",A17,IF(C17<>"",C17,IF(D17<>"",D17,IF(F17<>"",F17,"Error")))) -> FedEx (PlanRoot) | J17: =IF(A17<>"",1,IF(C17<>"",2,IF(D17<>"",3,IF(F17<>"",4,"Error")))) -> 1 | K17: =LEFT(I17, FIND("§", SUBSTITUTE(I17," (","§", (LEN(I17)-LEN(SUBSTITUTE(I17," (","")))/2)) - 1) -> FedEx | L17: =_xlfn.LET( _xlpm.p,FIND("§",SUBSTITUTE(I17," (","§",(LEN(I17)-LEN(SUBSTITUTE(I17," (","")))/2)), MID(I17,_xlpm.p+2,LEN(I17)-_xlpm.p-2)) -> PlanRoot
C18: DRIVE (190945) | I18: =IF(A18<>"",A18,IF(C18<>"",C18,IF(D18<>"",D18,IF(F18<>"",F18,"Error")))) -> DRIVE (190945) | J18: =IF(A18<>"",1,IF(C18<>"",2,IF(D18<>"",3,IF(F18<>"",4,"Error")))) -> 2 | K18: =LEFT(I18, FIND("§", SUBSTITUTE(I18," (","§", (LEN(I18)-LEN(SUBSTITUTE(I18," (","")))/2)) - 1) -> DRIVE | L18: =_xlfn.LET( _xlpm.p,FIND("§",SUBSTITUTE(I18," (","§",(LEN(I18)-LEN(SUBSTITUTE(I18," (","")))/2)), MID(I18,_xlpm.p+2,LEN(I18)-_xlpm.p-2)) -> 190945
D19: DRIVE (190946) | I19: =IF(A19<>"",A19,IF(C19<>"",C19,IF(D19<>"",D19,IF(F19<>"",F19,"Error")))) -> DRIVE (190946) | J19: =IF(A19<>"",1,IF(C19<>"",2,IF(D19<>"",3,IF(F19<>"",4,"Error")))) -> 3 | K19: =LEFT(I19, FIND("§", SUBSTITUTE(I19," (","§", (LEN(I19)-LEN(SUBSTITUTE(I19," (","")))/2)) - 1) -> DRIVE | L19: =_xlfn.LET( _xlpm.p,FIND("§",SUBSTITUTE(I19," (","§",(LEN(I19)-LEN(SUBSTITUTE(I19," (","")))/2)), MID(I19,_xlpm.p+2,LEN(I19)-_xlpm.p-2)) -> 190946
F20: DRIVE (190947) | I20: =IF(A20<>"",A20,IF(C20<>"",C20,IF(D20<>"",D20,IF(F20<>"",F20,"Error")))) -> DRIVE (190947) | J20: =IF(A20<>"",1,IF(C20<>"",2,IF(D20<>"",3,IF(F20<>"",4,"Error")))) -> 4 | K20: =LEFT(I20, FIND("§", SUBSTITUTE(I20," (","§", (LEN(I20)-LEN(SUBSTITUTE(I20," (","")))/2)) - 1) -> DRIVE | L20: =_xlfn.LET( _xlpm.p,FIND("§",SUBSTITUTE(I20," (","§",(LEN(I20)-LEN(SUBSTITUTE(I20," (","")))/2)), MID(I20,_xlpm.p+2,LEN(I20)-_xlpm.p-2)) -> 190947
F21: C-DRIVE (190948) | I21: =IF(A21<>"",A21,IF(C21<>"",C21,IF(D21<>"",D21,IF(F21<>"",F21,"Error")))) -> C-DRIVE (190948) | J21: =IF(A21<>"",1,IF(C21<>"",2,IF(D21<>"",3,IF(F21<>"",4,"Error")))) -> 4 | K21: =LEFT(I21, FIND("§", SUBSTITUTE(I21," (","§", (LEN(I21)-LEN(SUBSTITUTE(I21," (","")))/2)) - 1) -> C-DRIVE | L21: =_xlfn.LET( _xlpm.p,FIND("§",SUBSTITUTE(I21," (","§",(LEN(I21)-LEN(SUBSTITUTE(I21," (","")))/2)), MID(I21,_xlpm.p+2,LEN(I21)-_xlpm.p-2)) -> 190948
F22: P&C-DRIVE (191311) | I22: =IF(A22<>"",A22,IF(C22<>"",C22,IF(D22<>"",D22,IF(F22<>"",F22,"Error")))) -> P&C-DRIVE (191311) | J22: =IF(A22<>"",1,IF(C22<>"",2,IF(D22<>"",3,IF(F22<>"",4,"Error")))) -> 4 | K22: =LEFT(I22, FIND("§", SUBSTITUTE(I22," (","§", (LEN(I22)-LEN(SUBSTITUTE(I22," (","")))/2)) - 1) -> P&C-DRIVE | L22: =_xlfn.LET( _xlpm.p,FIND("§",SUBSTITUTE(I22," (","§",(LEN(I22)-LEN(SUBSTITUTE(I22," (","")))/2)), MID(I22,_xlpm.p+2,LEN(I22)-_xlpm.p-2)) -> 191311
C23: Non-DRIVE (190949) | I23: =IF(A23<>"",A23,IF(C23<>"",C23,IF(D23<>"",D23,IF(F23<>"",F23,"Error")))) -> Non-DRIVE (190949) | J23: =IF(A23<>"",1,IF(C23<>"",2,IF(D23<>"",3,IF(F23<>"",4,"Error")))) -> 2 | K23: =LEFT(I23, FIND("§", SUBSTITUTE(I23," (","§", (LEN(I23)-LEN(SUBSTITUTE(I23," (","")))/2)) - 1) -> Non-DRIVE | L23: =_xlfn.LET( _xlpm.p,FIND("§",SUBSTITUTE(I23," (","§",(LEN(I23)-LEN(SUBSTITUTE(I23," (","")))/2)), MID(I23,_xlpm.p+2,LEN(I23)-_xlpm.p-2)) -> 190949
D24: D&T (190950) | I24: =IF(A24<>"",A24,IF(C24<>"",C24,IF(D24<>"",D24,IF(F24<>"",F24,"Error")))) -> D&T (190950) | J24: =IF(A24<>"",1,IF(C24<>"",2,IF(D24<>"",3,IF(F24<>"",4,"Error")))) -> 3 | K24: =LEFT(I24, FIND("§", SUBSTITUTE(I24," (","§", (LEN(I24)-LEN(SUBSTITUTE(I24," (","")))/2)) - 1) -> D&T | L24: =_xlfn.LET( _xlpm.p,FIND("§",SUBSTITUTE(I24," (","§",(LEN(I24)-LEN(SUBSTITUTE(I24," (","")))/2)), MID(I24,_xlpm.p+2,LEN(I24)-_xlpm.p-2)) -> 190950
F25: Tech-Enabled Intake (191086) | I25: =IF(A25<>"",A25,IF(C25<>"",C25,IF(D25<>"",D25,IF(F25<>"",F25,"Error")))) -> Tech-Enabled Intake (191086) | J25: =IF(A25<>"",1,IF(C25<>"",2,IF(D25<>"",3,IF(F25<>"",4,"Error")))) -> 4 | K25: =LEFT(I25, FIND("§", SUBSTITUTE(I25," (","§", (LEN(I25)-LEN(SUBSTITUTE(I25," (","")))/2)) - 1) -> Tech-Enabled Intake | L25: =_xlfn.LET( _xlpm.p,FIND("§",SUBSTITUTE(I25," (","§",(LEN(I25)-LEN(SUBSTITUTE(I25," (","")))/2)), MID(I25,_xlpm.p+2,LEN(I25)-_xlpm.p-2)) -> 191086
F26: D&T Cross-Portfolio Demand (190951) | I26: =IF(A26<>"",A26,IF(C26<>"",C26,IF(D26<>"",D26,IF(F26<>"",F26,"Error")))) -> D&T Cross-Portfolio Demand (190951) | J26: =IF(A26<>"",1,IF(C26<>"",2,IF(D26<>"",3,IF(F26<>"",4,"Error")))) -> 4 | K26: =LEFT(I26, FIND("§", SUBSTITUTE(I26," (","§", (LEN(I26)-LEN(SUBSTITUTE(I26," (","")))/2)) - 1) -> D&T Cross-Portfolio Demand | L26: =_xlfn.LET( _xlpm.p,FIND("§",SUBSTITUTE(I26," (","§",(LEN(I26)-LEN(SUBSTITUTE(I26," (","")))/2)), MID(I26,_xlpm.p+2,LEN(I26)-_xlpm.p-2)) -> 190951
F27: C-D&T Cross-Portfolio Demand (191085) | I27: =IF(A27<>"",A27,IF(C27<>"",C27,IF(D27<>"",D27,IF(F27<>"",F27,"Error")))) -> C-D&T Cross-Portfolio Demand (191085) | J27: =IF(A27<>"",1,IF(C27<>"",2,IF(D27<>"",3,IF(F27<>"",4,"Error")))) -> 4 | K27: =LEFT(I27, FIND("§", SUBSTITUTE(I27," (","§", (LEN(I27)-LEN(SUBSTITUTE(I27," (","")))/2)) - 1) -> C-D&T Cross-Portfolio Demand | L27: =_xlfn.LET( _xlpm.p,FIND("§",SUBSTITUTE(I27," (","§",(LEN(I27)-LEN(SUBSTITUTE(I27," (","")))/2)), MID(I27,_xlpm.p+2,LEN(I27)-_xlpm.p-2)) -> 191085
F28: P&C-D&T Cross-Portfolio Demand (191312) | I28: =IF(A28<>"",A28,IF(C28<>"",C28,IF(D28<>"",D28,IF(F28<>"",F28,"Error")))) -> P&C-D&T Cross-Portfolio Demand (191312) | J28: =IF(A28<>"",1,IF(C28<>"",2,IF(D28<>"",3,IF(F28<>"",4,"Error")))) -> 4 | K28: =LEFT(I28, FIND("§", SUBSTITUTE(I28," (","§", (LEN(I28)-LEN(SUBSTITUTE(I28," (","")))/2)) - 1) -> P&C-D&T Cross-Portfolio Demand | L28: =_xlfn.LET( _xlpm.p,FIND("§",SUBSTITUTE(I28," (","§",(LEN(I28)-LEN(SUBSTITUTE(I28," (","")))/2)), MID(I28,_xlpm.p+2,LEN(I28)-_xlpm.p-2)) -> 191312
F29: D&T Strategic Demand (191179) | I29: =IF(A29<>"",A29,IF(C29<>"",C29,IF(D29<>"",D29,IF(F29<>"",F29,"Error")))) -> D&T Strategic Demand (191179) | J29: =IF(A29<>"",1,IF(C29<>"",2,IF(D29<>"",3,IF(F29<>"",4,"Error")))) -> 4 | K29: =LEFT(I29, FIND("§", SUBSTITUTE(I29," (","§", (LEN(I29)-LEN(SUBSTITUTE(I29," (","")))/2)) - 1) -> D&T Strategic Demand | L29: =_xlfn.LET( _xlpm.p,FIND("§",SUBSTITUTE(I29," (","§",(LEN(I29)-LEN(SUBSTITUTE(I29," (","")))/2)), MID(I29,_xlpm.p+2,LEN(I29)-_xlpm.p-2)) -> 191179
F30: C-D&T Strategic Demand (191180) | I30: =IF(A30<>"",A30,IF(C30<>"",C30,IF(D30<>"",D30,IF(F30<>"",F30,"Error")))) -> C-D&T Strategic Demand (191180) | J30: =IF(A30<>"",1,IF(C30<>"",2,IF(D30<>"",3,IF(F30<>"",4,"Error")))) -> 4 | K30: =LEFT(I30, FIND("§", SUBSTITUTE(I30," (","§", (LEN(I30)-LEN(SUBSTITUTE(I30," (","")))/2)) - 1) -> C-D&T Strategic Demand | L30: =_xlfn.LET( _xlpm.p,FIND("§",SUBSTITUTE(I30," (","§",(LEN(I30)-LEN(SUBSTITUTE(I30," (","")))/2)), MID(I30,_xlpm.p+2,LEN(I30)-_xlpm.p-2)) -> 191180
F31: P&C-D&T Strategic Demand (191313) | I31: =IF(A31<>"",A31,IF(C31<>"",C31,IF(D31<>"",D31,IF(F31<>"",F31,"Error")))) -> P&C-D&T Strategic Demand (191313) | J31: =IF(A31<>"",1,IF(C31<>"",2,IF(D31<>"",3,IF(F31<>"",4,"Error")))) -> 4 | K31: =LEFT(I31, FIND("§", SUBSTITUTE(I31," (","§", (LEN(I31)-LEN(SUBSTITUTE(I31," (","")))/2)) - 1) -> P&C-D&T Strategic Demand | L31: =_xlfn.LET( _xlpm.p,FIND("§",SUBSTITUTE(I31," (","§",(LEN(I31)-LEN(SUBSTITUTE(I31," (","")))/2)), MID(I31,_xlpm.p+2,LEN(I31)-_xlpm.p-2)) -> 191313
C32: C-Business Demand (191314) | I32: =IF(A32<>"",A32,IF(C32<>"",C32,IF(D32<>"",D32,IF(F32<>"",F32,"Error")))) -> C-Business Demand (191314) | J32: =IF(A32<>"",1,IF(C32<>"",2,IF(D32<>"",3,IF(F32<>"",4,"Error")))) -> 2 | K32: =LEFT(I32, FIND("§", SUBSTITUTE(I32," (","§", (LEN(I32)-LEN(SUBSTITUTE(I32," (","")))/2)) - 1) -> C-Business Demand | L32: =_xlfn.LET( _xlpm.p,FIND("§",SUBSTITUTE(I32," (","§",(LEN(I32)-LEN(SUBSTITUTE(I32," (","")))/2)), MID(I32,_xlpm.p+2,LEN(I32)-_xlpm.p-2)) -> 191314
D33: Americas International (191465) | I33: =IF(A33<>"",A33,IF(C33<>"",C33,IF(D33<>"",D33,IF(F33<>"",F33,"Error")))) -> Americas International (191465) | J33: =IF(A33<>"",1,IF(C33<>"",2,IF(D33<>"",3,IF(F33<>"",4,"Error")))) -> 3 | K33: =LEFT(I33, FIND("§", SUBSTITUTE(I33," (","§", (LEN(I33)-LEN(SUBSTITUTE(I33," (","")))/2)) - 1) -> Americas International | L33: =_xlfn.LET( _xlpm.p,FIND("§",SUBSTITUTE(I33," (","§",(LEN(I33)-LEN(SUBSTITUTE(I33," (","")))/2)), MID(I33,_xlpm.p+2,LEN(I33)-_xlpm.p-2)) -> 191465
D34: APAC (191466) | I34: =IF(A34<>"",A34,IF(C34<>"",C34,IF(D34<>"",D34,IF(F34<>"",F34,"Error")))) -> APAC (191466) | J34: =IF(A34<>"",1,IF(C34<>"",2,IF(D34<>"",3,IF(F34<>"",4,"Error")))) -> 3 | K34: =LEFT(I34, FIND("§", SUBSTITUTE(I34," (","§", (LEN(I34)-LEN(SUBSTITUTE(I34," (","")))/2)) - 1) -> APAC | L34: =_xlfn.LET( _xlpm.p,FIND("§",SUBSTITUTE(I34," (","§",(LEN(I34)-LEN(SUBSTITUTE(I34," (","")))/2)), MID(I34,_xlpm.p+2,LEN(I34)-_xlpm.p-2)) -> 191466
D35: Airline (191467) | I35: =IF(A35<>"",A35,IF(C35<>"",C35,IF(D35<>"",D35,IF(F35<>"",F35,"Error")))) -> Airline (191467) | J35: =IF(A35<>"",1,IF(C35<>"",2,IF(D35<>"",3,IF(F35<>"",4,"Error")))) -> 3 | K35: =LEFT(I35, FIND("§", SUBSTITUTE(I35," (","§", (LEN(I35)-LEN(SUBSTITUTE(I35," (","")))/2)) - 1) -> Airline | L35: =_xlfn.LET( _xlpm.p,FIND("§",SUBSTITUTE(I35," (","§",(LEN(I35)-LEN(SUBSTITUTE(I35," (","")))/2)), MID(I35,_xlpm.p+2,LEN(I35)-_xlpm.p-2)) -> 191467
D36: Commercial (191468) | I36: =IF(A36<>"",A36,IF(C36<>"",C36,IF(D36<>"",D36,IF(F36<>"",F36,"Error")))) -> Commercial (191468) | J36: =IF(A36<>"",1,IF(C36<>"",2,IF(D36<>"",3,IF(F36<>"",4,"Error")))) -> 3 | K36: =LEFT(I36, FIND("§", SUBSTITUTE(I36," (","§", (LEN(I36)-LEN(SUBSTITUTE(I36," (","")))/2)) - 1) -> Commercial | L36: =_xlfn.LET( _xlpm.p,FIND("§",SUBSTITUTE(I36," (","§",(LEN(I36)-LEN(SUBSTITUTE(I36," (","")))/2)), MID(I36,_xlpm.p+2,LEN(I36)-_xlpm.p-2)) -> 191468
D37: Data and Tech (191469) | I37: =IF(A37<>"",A37,IF(C37<>"",C37,IF(D37<>"",D37,IF(F37<>"",F37,"Error")))) -> Data and Tech (191469) | J37: =IF(A37<>"",1,IF(C37<>"",2,IF(D37<>"",3,IF(F37<>"",4,"Error")))) -> 3 | K37: =LEFT(I37, FIND("§", SUBSTITUTE(I37," (","§", (LEN(I37)-LEN(SUBSTITUTE(I37," (","")))/2)) - 1) -> Data and Tech | L37: =_xlfn.LET( _xlpm.p,FIND("§",SUBSTITUTE(I37," (","§",(LEN(I37)-LEN(SUBSTITUTE(I37," (","")))/2)), MID(I37,_xlpm.p+2,LEN(I37)-_xlpm.p-2)) -> 191469
D38: Dock (191470) | I38: =IF(A38<>"",A38,IF(C38<>"",C38,IF(D38<>"",D38,IF(F38<>"",F38,"Error")))) -> Dock (191470) | J38: =IF(A38<>"",1,IF(C38<>"",2,IF(D38<>"",3,IF(F38<>"",4,"Error")))) -> 3 | K38: =LEFT(I38, FIND("§", SUBSTITUTE(I38," (","§", (LEN(I38)-LEN(SUBSTITUTE(I38," (","")))/2)) - 1) -> Dock | L38: =_xlfn.LET( _xlpm.p,FIND("§",SUBSTITUTE(I38," (","§",(LEN(I38)-LEN(SUBSTITUTE(I38," (","")))/2)), MID(I38,_xlpm.p+2,LEN(I38)-_xlpm.p-2)) -> 191470
D39: Europe (191471) | I39: =IF(A39<>"",A39,IF(C39<>"",C39,IF(D39<>"",D39,IF(F39<>"",F39,"Error")))) -> Europe (191471) | J39: =IF(A39<>"",1,IF(C39<>"",2,IF(D39<>"",3,IF(F39<>"",4,"Error")))) -> 3 | K39: =LEFT(I39, FIND("§", SUBSTITUTE(I39," (","§", (LEN(I39)-LEN(SUBSTITUTE(I39," (","")))/2)) - 1) -> Europe | L39: =_xlfn.LET( _xlpm.p,FIND("§",SUBSTITUTE(I39," (","§",(LEN(I39)-LEN(SUBSTITUTE(I39," (","")))/2)), MID(I39,_xlpm.p+2,LEN(I39)-_xlpm.p-2)) -> 191471
D40: Freight (this one will likely not be included) (191472) | I40: =IF(A40<>"",A40,IF(C40<>"",C40,IF(D40<>"",D40,IF(F40<>"",F40,"Error")))) -> Freight (this one will likely not be included) (191472) | J40: =IF(A40<>"",1,IF(C40<>"",2,IF(D40<>"",3,IF(F40<>"",4,"Error")))) -> 3 | K40: =LEFT(I40, FIND("§", SUBSTITUTE(I40," (","§", (LEN(I40)-LEN(SUBSTITUTE(I40," (","")))/2)) - 1) -> Freight (this one will likely not be included) | L40: =_xlfn.LET( _xlpm.p,FIND("§",SUBSTITUTE(I40," (","§",(LEN(I40)-LEN(SUBSTITUTE(I40," (","")))/2)), MID(I40,_xlpm.p+2,LEN(I40)-_xlpm.p-2)) -> 191472
D41: Global Air Hubs & Ramps (191473) | I41: =IF(A41<>"",A41,IF(C41<>"",C41,IF(D41<>"",D41,IF(F41<>"",F41,"Error")))) -> Global Air Hubs & Ramps (191473) | J41: =IF(A41<>"",1,IF(C41<>"",2,IF(D41<>"",3,IF(F41<>"",4,"Error")))) -> 3 | K41: =LEFT(I41, FIND("§", SUBSTITUTE(I41," (","§", (LEN(I41)-LEN(SUBSTITUTE(I41," (","")))/2)) - 1) -> Global Air Hubs & Ramps | L41: =_xlfn.LET( _xlpm.p,FIND("§",SUBSTITUTE(I41," (","§",(LEN(I41)-LEN(SUBSTITUTE(I41," (","")))/2)), MID(I41,_xlpm.p+2,LEN(I41)-_xlpm.p-2)) -> 191473
D42: Global Capabilities Strategy (191474) | I42: =IF(A42<>"",A42,IF(C42<>"",C42,IF(D42<>"",D42,IF(F42<>"",F42,"Error")))) -> Global Capabilities Strategy (191474) | J42: =IF(A42<>"",1,IF(C42<>"",2,IF(D42<>"",3,IF(F42<>"",4,"Error")))) -> 3 | K42: =LEFT(I42, FIND("§", SUBSTITUTE(I42," (","§", (LEN(I42)-LEN(SUBSTITUTE(I42," (","")))/2)) - 1) -> Global Capabilities Strategy | L42: =_xlfn.LET( _xlpm.p,FIND("§",SUBSTITUTE(I42," (","§",(LEN(I42)-LEN(SUBSTITUTE(I42," (","")))/2)), MID(I42,_xlpm.p+2,LEN(I42)-_xlpm.p-2)) -> 191474
D43: Global Clearance (191475) | I43: =IF(A43<>"",A43,IF(C43<>"",C43,IF(D43<>"",D43,IF(F43<>"",F43,"Error")))) -> Global Clearance (191475) | J43: =IF(A43<>"",1,IF(C43<>"",2,IF(D43<>"",3,IF(F43<>"",4,"Error")))) -> 3 | K43: =LEFT(I43, FIND("§", SUBSTITUTE(I43," (","§", (LEN(I43)-LEN(SUBSTITUTE(I43," (","")))/2)) - 1) -> Global Clearance | L43: =_xlfn.LET( _xlpm.p,FIND("§",SUBSTITUTE(I43," (","§",(LEN(I43)-LEN(SUBSTITUTE(I43," (","")))/2)), MID(I43,_xlpm.p+2,LEN(I43)-_xlpm.p-2)) -> 191475
...

Sheet View - Attributes by Screen
A4: Lifecycle Stage | B4: Order | C4: Target Field Name | D4: Add New Request Information | E4: Business Continuity Assessment | F4: Problem Opportunity Statement | G4: Triage Validation | H4: Request Approval | I4: Move Work and Assign Roles and Responsibilities | J4: Architecture Alignment | K4: Certified Business Case | L4: SL3 EPG Approval | M4: SL3 Finance Approval | N4: Demand Bundle Decomp and Conceptual Architecture | O4: Detailed Milestone Refinement | P4: EPM Quality Check 1 | Q4: Revised Implementation Plan/Sequence Delivery | R4: Epic Approval | S4: L3 Epic Solutioning | T4: L3 D&T Costing | U4: EPM Quality Check 2 | V4: L3: Execute and Release | W4: SL4 Close Demand Bundle Business Finance Approval | X4: Evaluate Outcome Achievement
A5: L1 | B5: 1 | C5: Work ID
A6: L1 | B6: 2 | C6: Work Name
A7: L1 | B7: 3 | C7: Work Parent
A8: L1 | B8: 4 | C8: Work Type
A9: L1 | B9: 5 | C9: Does this request support a DRIVE strategic program?
A10: L1 | B10: 6 | C10: Does this require Limited Visibility?
A11: L1 | B11: 7 | C11: Is this demand Business Only?
A12: L1 | B12: 9 | C12: Does this request support a D&T Digital Transformation Program?
A13: L1 | B13: 10 | C13: Demand Manager
A14: L1 | B14: 11 | C14: VP Sponsor
A15: L1 | B15: 12 | C15: Does this request support a planned application or infrastructure upgrade and/or a routine infrastructure refresh?
A16: L1 | B16: 13 | C16: Risk Subtype (Does this request address a risk or requirement to one of the following?)
... A25: L1 | B25: 22 | C25: Requested IT completion Date
A26: L1 | B26: 23 | C26: Demand Type | D26: RO | E26: RO | F26: RO | G26: RW
A27: L1 | B27: 24 | C27: What business problem are you looking to solve?
A28: L1 | B28: 25 | C28: Why is this needed?
A29: L1 | B29: 26 | C29: What is the risk if not done?
A30: L1 | B30: 27 | C30: Business Ability To Statements
A31: L1 | B31: 28 | C31: Expected Business Outcome
A32: L1 | B32: 29 | C32: T-shirt Size
A33: L1 | B33: 30 | C33: Estimated Annualized Value Range
A34: L1 | B34: 31 | C34: Explain how you arrived at the estimated value range above
A35: L1 | B35: 32 | C35: Primary Type of Value
A36: L1 | B36: 33 | C36: Primary Type of Value Impact
A37: L1 | B37: 34 | C37: Primary Impacted Portfolio
A38: L1 | B38: 35 | C38: Other Impacted Portfolios
... A58: L1 | B58: 4.1 | C58: Does this work support either of these type of Programs?
A59: L1 | B59: Drive001 | C59: Name
A60: L1 | B60: Drive002 | C60: Strategic Parent
A61: L1 | B61: Drive003 | C61: Brief Demand Description
A62: L1 | B62: Drive004 | C62: Target Start
A63: L1 | B63: Drive005 | C63: Target Finish
A64: L1 | B64: Drive006 | C64: Program Owner
A65: L1 | B65: Drive007 | C65: Program Manager
A66: L1 | B66: Drive009 | C66: ESPM
A67: L1 | B67: Drive011 | C67: Architecture Program Manager
A68: L1 | B68: Drive012 | C68: TO Finance
A69: L1 | B69: Drive013 | C69: TO Approver
A70: L1 | B70: Drive014 | C70: EPM
...

Sheet View- Task & Risk Attributes
A1: Target Entity | B1: Epic - Task
A3: Order | B3: Target Field Name | C3: Source PROD ID | D3: Prod Source field name | E3: Sandbox A field name
A4: 95 | B4: Name | C4: DESCR | D4: Epic Name | E4: (blank)
A5: T01 | B5: Parent Sequence ID | C5: WORK_STRUCTURE_CODE | D5: Sequence ID | E5: (blank)
A6: T02 | B6: Parent Work ID | C6: PW_SHORT_NAME | D6: Work ID | E6: (blank)
A7: T03 | B7: Sequence ID | C7: WORK_STRUCTURE_CODE | D7: Sequence ID | E7: (blank)
A8: T04 | B8: Name | C8: pveDescription | D8: 0-Not Found | E8: (blank)
A9: T05 | B9: Description | C9: PE01 | D9: Work Description | E9: (blank)
A10: T06 | B10: Task or Milestone Type | C10: WBS712 | D10: Milestone Type | E10: (blank)
A11: T07 | B11: Execution Type | C11: ExecType | D11: Execution Type | E11: (blank)
A12: T08 | B12: Milestone Flag | C12: MILESTONE_FLAG | D12: Milestone Flag | E12: (blank)
A13: T09 | B13: Milestone/Task Owner | C13: fdx_task_owner | D13: Milestone/Task Owner | E13: (blank)
A14: T10 | B14: Work Status | C14: Wbs20 | D14: Work Status | E14: (blank)
A15: T11 | B15: Schedule Start | C15: SCHEDULE_START | D15: Schedule Start | E15: (blank)
A16: T12 | B16: Schedule Finish | C16: SCHEDULE_FINISH | D16: Schedule Finish | E16: (blank)
... A23: T19 | B23: Show on Roadmap | C23: Wbs19 | D23: Show on Roadmap | E23: (blank)
A28: Target Entity | B28: RISK
A30: Order | B30: Target Field Name | C30: Source PROD ID | D30: Prod Source field name | E30: Sandbox A field name
A31: RSK001 | B31: Parent Sequence ID | C31: WORK_STRUCTURE_CODE | D31: Sequence ID | E31: (blank)
A32: RSK002 | B32: Parent Work ID | C32: PW_SHORT_NAME | D32: Work ID | E32: (blank)
A33: RSK01 | B33: Name | C33: (blank) | D33: 0-Not Found | E33: (blank)
A34: RSK02 | B34: Description | C34: (blank) | D34: 0-Not Found | E34: (blank)
A35: RSK03 | B35: Risk Type | C35: Rsk31 | D35: Risk Type | E35: (blank)
A36: RSK04 | B36: Probability | C36: Rsk30 | D36: Risk Probability | E36: (blank)
A37: RSK05 | B37: Impact | C37: CRI8 | D37: 0-Not Found | E37: (blank)
A38: RSK06 | B38: Risk Mitigation Comments | C38: RISK_PLAN | D38: Risk Mitigation Comments | E38: (blank)
A39: RSK07 | B39: Assignee | C39: fdx_risk_owner | D39: Risk Owner | E39: (blank)
A40: RSK08 | B40: Due Date | C40: CRI_TARGETDATE | D40: Target Date | E40: (blank)
A41: RSK09 | B41: Created By | C41: CRI_OWNER | D41: Creator | E41: (blank)
... A43: RSK11 | B43: Last Updated By | C43: (blank) | D43: 0-Not Found | E43: (blank)

Sheet Strategic Req_historical
A1: Source Tab | B1: Primary Reviewer | C1: Op Model Step | D1: 1st Lifecycle Step Name | E1: Section Name | F1: Lifecycle Screen User Role | G1: Lifecycle Stage | H1: Order | I1: Source Demand Type | J1: Target Demand Type | K1: Target Entity | L1: Entity|ID | M1: Target Field Name | N1: Configuration Status | O1: Change Control Comments | P1: Notes/Comments | Q1: Current Attribute in FDXPROD? | R1: Current Attribute in FDXSANDBOXA? | S1: PROD ID | T1: FDXSANDBOXA ID | U1: DEV SB ID | V1: Data Migration Comments | W1: Able to Migrate Mock 1? | X1: Prod Source field name | Y1: Sandbox A field name | Z1: New instance Target field name | AA1: Field names Match (prod to new)? | AB1: Field names Match (Requirement to config)? | AC1: Type | AD1: Value Type | AE1: Selection Type | AF1: Has Dropdown | AG1: Values | AH1: Hover Text or Static Text | AI1: Options (Req./RO/Opt.) | AJ1: Editable After Submission | AK1: Permission Options | AL1: Restrict Permissions Forwarding | AM1: Needed in Roadmaps? | AN1: Column1 | AO1: Exists already? (ID) | AP1: Exists already (Name) | AQ1: Double mismatch? | AR1: Decision
A2: L1 - Strategy Def | B2: Christina | C2: L1: Program Established | D2: Add New Strategy | F2: ESPM | G2: L1 | H2: Drive001 | M2: Name | Q2: Yes | R2: Yes | S2: strat_name | T2: strat_name | U2: strat_name | AC2: Field | AD2: Text | AH2: Name of the strategic program | AI2: Req. | AJ2: Editable throughout | AM2: Yes | AO2: =IF(ISNUMBER(_xlfn.XMATCH(Table182[[#This Row],[DEV SB ID]],Platinum_Config[Target DEV SB ID],0))=FALSE,"No Match","Match") -> Match | AP2: =IF(ISNUMBER(_xlfn.XMATCH(Table182[[#This Row],[Target Field Name]],Platinum_Config[Target Field Name],0))=FALSE,"No Match","Match") -> Match | AQ2: =IF(AND(Table182[[#This Row],[Exists already? (ID)]]="No Match",Table182[[#This Row],[Exists already (Name)]]="No Match"),"No Match",IF(AND(Table182[[#This Row],[Exists already? (ID)]]="Match",Table182[[#This Row],[Exists already (Name)]]="Match"),"Double Match","One Match")) -> Double Match | AR2: Added
A3: L1 - Strategy Def | B3: Christina | C3: L1: Program Established | D3: Add New Strategy | F3: ESPM | G3: L1 | H3: Drive002 | M3: Strategic Parent | Q3: Yes | R3: Yes | S3: StratRoot | T3: StratRoot | U3: StratRoot | AC3: Strategic Hierarchy | AD3: L4 | AH3: Name of the strategic pillar the program is associated with | AI3: Req. | AJ3: Admin only | AO3: =IF(ISNUMBER(_xlfn.XMATCH(Table182[[#This Row],[DEV SB ID]],Platinum_Config[Target DEV SB ID],0))=FALSE,"No Match","Match") -> Match | AP3: =IF(ISNUMBER(_xlfn.XMATCH(Table182[[#This Row],[Target Field Name]],Platinum_Config[Target Field Name],0))=FALSE,"No Match","Match") -> Match | AQ3: =IF(AND(Table182[[#This Row],[Exists already? (ID)]]="No Match",Table182[[#This Row],[Exists already (Name)]]="No Match"),"No Match",IF(AND(Table182[[#This Row],[Exists already? (ID)]]="Match",Table182[[#This Row],[Exists already (Name)]]="Match"),"Double Match","One Match")) -> Double Match | AR3: Added
A4: L1 - Strategy Def | B4: Christina | C4: L1: Program Established | D4: Add New Strategy | F4: ESPM | G4: L1 | H4: Drive003 | M4: Brief Demand Description | Q4: Yes | R4: Yes | S4: strat_descr | T4: strat_descr | U4: strat_descr | AC4: Field | AD4: Text | AH4: A short summary (3-5 sentences) outlining the purpose and scope of the demand. Update: Describe how the program supports key organizational goals (e.g., growth, efficiency, compliance), the specific challenge or gap it addresses, and the defined scope of what is included and excluded. | AI4: Req. | AJ4: Editable throughout | AM4: Yes | AO4: =IF(ISNUMBER(_xlfn.XMATCH(Table182[[#This Row],[DEV SB ID]],Platinum_Config[Target DEV SB ID],0))=FALSE,"No Match","Match") -> Match | AP4: =IF(ISNUMBER(_xlfn.XMATCH(Table182[[#This Row],[Target Field Name]],Platinum_Config[Target Field Name],0))=FALSE,"No Match","Match") -> Match | AQ4: =IF(AND(Table182[[#This Row],[Exists already? (ID)]]="No Match",Table182[[#This Row],[Exists already (Name)]]="No Match"),"No Match",IF(AND(Table182[[#This Row],[Exists already? (ID)]]="Match",Table182[[#This Row],[Exists already (Name)]]="Match"),"Double Match","One Match")) -> Double Match | AR4: Added
A5: L1 - Strategy Def | B5: Christina | C5: L1: Program Established | D5: Add New Strategy | F5: ESPM | G5: L1 | H5: Drive004 | M5: Target Start | Q5: Yes | R5: Yes | S5: strat_target_start | T5: strat_target_start | U5: strat_target_start | AC5: Field | AD5: Date | AH5: Target Start of the strategic program | AI5: Opt. | AJ5: Editable up to Step 2 | AM5: Yes | AO5: =IF(ISNUMBER(_xlfn.XMATCH(Table182[[#This Row],[DEV SB ID]],Platinum_Config[Target DEV SB ID],0))=FALSE,"No Match","Match") -> Match | AP5: =IF(ISNUMBER(_xlfn.XMATCH(Table182[[#This Row],[Target Field Name]],Platinum_Config[Target Field Name],0))=FALSE,"No Match","Match") -> Match | AQ5: =IF(AND(Table182[[#This Row],[Exists already? (ID)]]="No Match",Table182[[#This Row],[Exists already (Name)]]="No Match"),"No Match",IF(AND(Table182[[#This Row],[Exists already? (ID)]]="Match",Table182[[#This Row],[Exists already (Name)]]="Match"),"Double Match","One Match")) -> Double Match | AR5: Added
A6: L1 - Strategy Def | B6: Christina | C6: L1: Program Established | D6: Add New Strategy | F6: ESPM | G6: L1 | H6: Drive005 | M6: Target Finish | Q6: Yes | R6: Yes | S6: strat_target_finish | T6: strat_target_finish | U6: strat_target_finish | AC6: Field | AD6: Date | AH6: Target Finish of the strategic program | AI6: Opt. | AJ6: Editable up to Step 2 | AM6: Yes | AO6: =IF(ISNUMBER(_xlfn.XMATCH(Table182[[#This Row],[DEV SB ID]],Platinum_Config[Target DEV SB ID],0))=FALSE,"No Match","Match") -> Match | AP6: =IF(ISNUMBER(_xlfn.XMATCH(Table182[[#This Row],[Target Field Name]],Platinum_Config[Target Field Name],0))=FALSE,"No Match","Match") -> Match | AQ6: =IF(AND(Table182[[#This Row],[Exists already? (ID)]]="No Match",Table182[[#This Row],[Exists already (Name)]]="No Match"),"No Match",IF(AND(Table182[[#This Row],[Exists already? (ID)]]="Match",Table182[[#This Row],[Exists already (Name)]]="Match"),"Double Match","One Match")) -> Double Match | AR6: Added
A7: L1 - Strategy Def | B7: Christina | C7: L1: Program Established | D7: Assign Roles and Responsibilities | F7: ESPM | G7: L1 | H7: Drive006 | M7: Program Owner | P7: Lifecycle Roles do not support Help/Hover text | Q7: No | R7: Yes | T7: 178308 | U7: 190983 | AC7: Field | AD7: Text | AE7: Single | AG7: dynamic | AH7: The individual responsible for overseeing the strategy, execution, governance, and outcomes of a program. This role ensures that all work within the program collectively achieves the intended business objectives and deliver measurable value.​ | AI7: Req. | AJ7: Editable throughout | AK7: RW | AL7: Yes | AO7: =IF(ISNUMBER(_xlfn.XMATCH(Table182[[#This Row],[DEV SB ID]],Platinum_Config[Target DEV SB ID],0))=FALSE,"No Match","Match") -> Match | AP7: =IF(ISNUMBER(_xlfn.XMATCH(Table182[[#This Row],[Target Field Name]],Platinum_Config[Target Field Name],0))=FALSE,"No Match","Match") -> Match | AQ7: =IF(AND(Table182[[#This Row],[Exists already? (ID)]]="No Match",Table182[[#This Row],[Exists already (Name)]]="No Match"),"No Match",IF(AND(Table182[[#This Row],[Exists already? (ID)]]="Match",Table182[[#This Row],[Exists already (Name)]]="Match"),"Double Match","One Match")) -> Double Match | AR7: Added
A8: L1 - Strategy Def | B8: Christina | C8: L1: Program Established | D8: Assign Roles and Responsibilities | F8: ESPM | G8: L1 | H8: Drive007 | M8: Program Manager | P8: Lifecycle Roles do not support Help/Hover text | Q8: No | R8: Yes | T8: 178309 | U8: 190984 | AC8: Field | AD8: Text | AE8: Multi | AG8: dynamic | AH8: The individual(s) is responsible for planning, coordinating, and overseeing the execution of a program to ensure it delivers its intended strategic business outcomes. This role focuses on integrated delivery, governance, risk management, and cross‑team alignment to ensure all workstreams operate cohesively and effectively.​ | AI8: Req. | AJ8: Editable throughout | AK8: RW | AL8: Yes | AO8: =IF(ISNUMBER(_xlfn.XMATCH(Table182[[#This Row],[DEV SB ID]],Platinum_Config[Target DEV SB ID],0))=FALSE,"No Match","Match") -> Match | AP8: =IF(ISNUMBER(_xlfn.XMATCH(Table182[[#This Row],[Target Field Name]],Platinum_Config[Target Field Name],0))=FALSE,"No Match","Match") -> Match | AQ8: =IF(AND(Table182[[#This Row],[Exists already? (ID)]]="No Match",Table182[[#This Row],[Exists already (Name)]]="No Match"),"No Match",IF(AND(Table182[[#This Row],[Exists already? (ID)]]="Match",Table182[[#This Row],[Exists already (Name)]]="Match"),"Double Match","One Match")) -> Double Match | AR8: Added
A9: L1 - Strategy Def | B9: Christina | C9: L1: Program Established | D9: Assign Roles and Responsibilities | F9: ESPM | G9: L1 | H9: Drive008 | M9: D&T Captain | P9: Lifecycle Roles do not support Help/Hover text | Q9: No | R9: Yes | T9: 178311 | U9: 190985 | AC9: Field | AD9: Text | AE9: Single | AG9: dynamic | AH9: The designated leader within a strategic program who is accountable for driving the data, technology, and systems‑related components required to achieve program goals. This role ensures that data capabilities, technical solutions, and digital processes are aligned with the program’s strategy, integrated effectively, and able to support long‑term scalability | AI9: Req. | AJ9: Editable throughout | AK9: RW | AL9: Yes | AO9: =IF(ISNUMBER(_xlfn.XMATCH(Table182[[#This Row],[DEV SB ID]],Platinum_Config[Target DEV SB ID],0))=FALSE,"No Match","Match") -> No Match | AP9: =IF(ISNUMBER(_xlfn.XMATCH(Table182[[#This Row],[Target Field Name]],Platinum_Config[Target Field Name],0))=FALSE,"No Match","Match") -> Match | AQ9: =IF(AND(Table182[[#This Row],[Exists already? (ID)]]="No Match",Table182[[#This Row],[Exists already (Name)]]="No Match"),"No Match",IF(AND(Table182[[#This Row],[Exists already? (ID)]]="Match",Table182[[#This Row],[Exists already (Name)]]="Match"),"Double Match","One Match")) -> One Match | AR9: Ignore
A10: L1 - Strategy Def | B10: Christina | C10: L1: Program Established | D10: Assign Roles and Responsibilities | F10: ESPM | G10: L1 | H10: Drive009 | M10: ESPM | P10: Lifecycle Roles do not support Help/Hover text | Q10: No | R10: Yes | T10: 178312 | U10: 190986 | AC10: Field | AD10: Text | AE10: Multi | AG10: dynamic | AH10: Centralized group that partners with program managers and business owners to guide the planning, alignment, and execution of strategic programs across the organization. They ensure programs are designed, prioritized, and managed in a way that advances enterprise‑level goals. | AI10: Req. | AJ10: Editable throughout | AK10: RW | AL10: Yes | AO10: =IF(ISNUMBER(_xlfn.XMATCH(Table182[[#This Row],[DEV SB ID]],Platinum_Config[Target DEV SB ID],0))=FALSE,"No Match","Match") -> Match | AP10: =IF(ISNUMBER(_xlfn.XMATCH(Table182[[#This Row],[Target Field Name]],Platinum_Config[Target Field Name],0))=FALSE,"No Match","Match") -> Match | AQ10: =IF(AND(Table182[[#This Row],[Exists already? (ID)]]="No Match",Table182[[#This Row],[Exists already (Name)]]="No Match"),"No Match",IF(AND(Table182[[#This Row],[Exists already? (ID)]]="Match",Table182[[#This Row],[Exists already (Name)]]="Match"),"Double Match","One Match")) -> Double Match | AR10: Added
A11: L1 - Strategy Def | B11: Christina | C11: L1: Program Established | D11: Assign Roles and Responsibilities | F11: ESPM | G11: L1 | H11: Drive010 | M11: Business Finance | P11: [CD] - Asked Matt Buxton for assistance with definition Lifecycle Roles do not support Help/Hover text | Q11: No | R11: Yes | T11: 178340 | U11: 190987 | AC11: Field | AD11: Text | AE11: Multi | AG11: dynamic | AI11: Req. | AJ11: Editable throughout | AK11: RW | AL11: Yes | AO11: =IF(ISNUMBER(_xlfn.XMATCH(Table182[[#This Row],[DEV SB ID]],Platinum_Config[Target DEV SB ID],0))=FALSE,"No Match","Match") -> No Match | AP11: =IF(ISNUMBER(_xlfn.XMATCH(Table182[[#This Row],[Target Field Name]],Platinum_Config[Target Field Name],0))=FALSE,"No Match","Match") -> Match | AQ11: =IF(AND(Table182[[#This Row],[Exists already? (ID)]]="No Match",Table182[[#This Row],[Exists already (Name)]]="No Match"),"No Match",IF(AND(Table182[[#This Row],[Exists already? (ID)]]="Match",Table182[[#This Row],[Exists already (Name)]]="Match"),"Double Match","One Match")) -> One Match | AR11: Ignore
A12: L1 - Strategy Def | B12: Christina | C12: L1: Program Established | D12: Assign Roles and Responsibilities | F12: ESPM | G12: L1 | H12: Drive011 | M12: Architecture Program Manager | P12: Should not have edit access to financials Lifecycle Roles do not support Help/Hover text | Q12: No | R12: Yes | T12: 178310 | U12: 190988 | AC12: Field | AD12: Text | AE12: Single | AG12: dynamic | AH12: Architectural role accountable for ensuring the program’s solutions align with enterprise strategy, architecture standards, and target-state blueprints. The EA Lead steers architectural direction, orchestrates cross-domain design decisions (business, data, application, integration, security, and infrastructure), and manages architectural risk and technical debt at the program level. The role facilitates decision-making and enforces guardrails through governance but does not directly own product delivery or approve business scope.​ | AI12: Opt. | AJ12: Editable throughout | AK12: RW | AL12: Yes | AO12: =IF(ISNUMBER(_xlfn.XMATCH(Table182[[#This Row],[DEV SB ID]],Platinum_Config[Target DEV SB ID],0))=FALSE,"No Match","Match") -> Match | AP12: =IF(ISNUMBER(_xlfn.XMATCH(Table182[[#This Row],[Target Field Name]],Platinum_Config[Target Field Name],0))=FALSE,"No Match","Match") -> Match | AQ12: =IF(AND(Table182[[#This Row],[Exists already? (ID)]]="No Match",Table182[[#This Row],[Exists already (Name)]]="No Match"),"No Match",IF(AND(Table182[[#This Row],[Exists already? (ID)]]="Match",Table182[[#This Row],[Exists already (Name)]]="Match"),"Double Match","One Match")) -> Double Match | AR12: Added
A13: L1 - Strategy Def | B13: Christina | C13: L1: Program Established | D13: Assign Roles and Responsibilities | F13: ESPM | G13: L1 | H13: Drive012 | M13: TO Finance | P13: [CD] - Asked Matt Buxton for assistance with definition Lifecycle Roles do not support Help/Hover text | Q13: Yes | R13: Yes | S13: 3399 | T13: 3399 | U13: 3399 | AC13: Field | AD13: Text | AE13: Single | AG13: dynamic | AH13: NA | AI13: Req. | AJ13: Editable throughout | AK13: RW | AL13: Yes | AO13: =IF(ISNUMBER(_xlfn.XMATCH(Table182[[#This Row],[DEV SB ID]],Platinum_Config[Target DEV SB ID],0))=FALSE,"No Match","Match") -> Match | AP13: =IF(ISNUMBER(_xlfn.XMATCH(Table182[[#This Row],[Target Field Name]],Platinum_Config[Target Field Name],0))=FALSE,"No Match","Match") -> Match | AQ13: =IF(AND(Table182[[#This Row],[Exists already? (ID)]]="No Match",Table182[[#This Row],[Exists already (Name)]]="No Match"),"No Match",IF(AND(Table182[[#This Row],[Exists already? (ID)]]="Match",Table182[[#This Row],[Exists already (Name)]]="Match"),"Double Match","One Match")) -> Double Match | AR13: Added
A14: L1 - Strategy Def | B14: Christina | C14: L1: Program Established | D14: Assign Roles and Responsibilities | F14: ESPM | G14: L1 | H14: Drive013 | M14: TO Approver | P14: Lifecycle Roles do not support Help/Hover text | Q14: No | R14: Yes | T14: 178339 | U14: 190989 | AC14: Field | AD14: Text | AE14: Multi | AG14: dynamic | AH14: Enterprise‑designated decision authority responsible for evaluating and formally approving programs and value bundles to progress to the next stage of the transformation lifecycle. This role ensures that each program and value bundle meets established strategic, financial, and operational criteria; aligns with enterprise priorities; and possesses the necessary readiness, resourcing, and value validation before advancing | AI14: Req. | AJ14: Editable throughout | AK14: RW | AL14: Yes | AO14: =IF(ISNUMBER(_xlfn.XMATCH(Table182[[#This Row],[DEV SB ID]],Platinum_Config[Target DEV SB ID],0))=FALSE,"No Match","Match") -> Match | AP14: =IF(ISNUMBER(_xlfn.XMATCH(Table182[[#This Row],[Target Field Name]],Platinum_Config[Target Field Name],0))=FALSE,"No Match","Match") -> Match | AQ14: =IF(AND(Table182[[#This Row],[Exists already? (ID)]]="No Match",Table182[[#This Row],[Exists already (Name)]]="No Match"),"No Match",IF(AND(Table182[[#This Row],[Exists already? (ID)]]="Match",Table182[[#This Row],[Exists already (Name)]]="Match"),"Double Match","One Match")) -> Double Match | AR14: Added
A15: L1 - Strategy Def | B15: Christina | C15: L1: Program Established | D15: Assign Roles and Responsibilities | F15: ESPM | G15: L1 | H15: Drive014 | M15: EPM | P15: Lifecycle Roles do not support Help/Hover text | Q15: Yes | R15: Yes | S15: 4181 | T15: 4181 | U15: 4181 | AC15: Field | AD15: Text | AE15: Multi | AG15: dynamic | AI15: Req. | AJ15: Editable throughout | AK15: RW | AL15: Yes | AO15: =IF(ISNUMBER(_xlfn.XMATCH(Table182[[#This Row],[DEV SB ID]],Platinum_Config[Target DEV SB ID],0))=FALSE,"No Match","Match") -> Match | AP15: =IF(ISNUMBER(_xlfn.XMATCH(Table182[[#This Row],[Target Field Name]],Platinum_Config[Target Field Name],0))=FALSE,"No Match","Match") -> Match | AQ15: =IF(AND(Table182[[#This Row],[Exists already? (ID)]]="No Match",Table182[[#This Row],[Exists already (Name)]]="No Match"),"No Match",IF(AND(Table182[[#This Row],[Exists already? (ID)]]="Match",Table182[[#This Row],[Exists already (Name)]]="Match"),"Double Match","One Match")) -> Double Match | AR15: Added
A16: L1 - Strategy Def | B16: Matt | C16: L1: Desired Business Outcomes and Business Case | D16: Initial Light Business Case | F16: Business Finance | G16: L1 | H16: Drive015 | M16: Expected Business Outcome | P16: Decide editability after L0/L1 | Q16: Yes | R16: Yes | S16: fdx_biz_out_strat | T16: fdx_biz_out_strat | U16: fdx_biz_out_strat | AC16: Field | AD16: Text | AH16: Summarize the why, what, and expected value of the program. | AI16: Opt. | AM16: Yes | AO16: =IF(ISNUMBER(_xlfn.XMATCH(Table182[[#This Row],[DEV SB ID]],Platinum_Config[Target DEV SB ID],0))=FALSE,"No Match","Match") -> Match | AP16: =IF(ISNUMBER(_xlfn.XMATCH(Table182[[#This Row],[Target Field Name]],Platinum_Config[Target Field Name],0))=FALSE,"No Match","Match") -> Match | AQ16: =IF(AND(Table182[[#This Row],[Exists already? (ID)]]="No Match",Table182[[#This Row],[Exists already (Name)]]="No Match"),"No Match",IF(AND(Table182[[#This Row],[Exists already? (ID)]]="Match",Table182[[#This Row],[Exists already (Name)]]="Match"),"Double Match","One Match")) -> Double Match | AR16: Added
A17: L1 - Strategy Def | B17: Matt | C17: L1: Desired Business Outcomes and Business Case | D17: Initial Light Business Case | F17: Business Finance | G17: L1 | H17: Drive016 | M17: Initial Net Recurring Benefits ($, annualized)-P&L/Hard | P17: Have static text above this saying "**Net Recurring Benefits = CY '29 Exit Rate, Annualized** | Q17: Yes | R17: Yes | S17: fdx_l1_nrb_hard | T17: fdx_l1_nrb_hard | U17: fdx_l1_nrb_hard | AC17: Field | AD17: Currency | AH17: Net Recurring Benefits = CY28 Exit Rate, Annualized P&L/Hard = direct impact to the P&L over baseline | AI17: Opt. | AM17: Yes | AO17: =IF(ISNUMBER(_xlfn.XMATCH(Table182[[#This Row],[DEV SB ID]],Platinum_Config[Target DEV SB ID],0))=FALSE,"No Match","Match") -> Match | AP17: =IF(ISNUMBER(_xlfn.XMATCH(Table182[[#This Row],[Target Field Name]],Platinum_Config[Target Field Name],0))=FALSE,"No Match","Match") -> Match | AQ17: =IF(AND(Table182[[#This Row],[Exists already? (ID)]]="No Match",Table182[[#This Row],[Exists already (Name)]]="No Match"),"No Match",IF(AND(Table182[[#This Row],[Exists already? (ID)]]="Match",Table182[[#This Row],[Exists already (Name)]]="Match"),"Double Match","One Match")) -> Double Match | AR17: Added
A18: L1 - Strategy Def | B18: Matt | C18: L1: Desired Business Outcomes and Business Case | D18: Initial Light Business Case | F18: Business Finance | G18: L1 | H18: Drive017 | M18: Initial Net Recurring Benefits ($, annualized)-Soft | P18: replace L1 with Initial; Follow up with finance to update definition; decide editability after L0/L1 | Q18: Yes | R18: Yes | S18: fdx_l1_nrb_soft | T18: fdx_l1_nrb_soft | U18: fdx_l1_nrb_soft | AC18: Field | AD18: Currency | AH18: Net Recurring Benefits = CY28 Exit Rate, Annualized Soft = direct impact to the P&L over baseline. i.e. Cost avoidance, improved productivity | AI18: Opt. | AM18: Yes | AO18: =IF(ISNUMBER(_xlfn.XMATCH(Table182[[#This Row],[DEV SB ID]],Platinum_Config[Target DEV SB ID],0))=FALSE,"No Match","Match") -> No Match | AP18: =IF(ISNUMBER(_xlfn.XMATCH(Table182[[#This Row],[Target Field Name]],Platinum_Config[Target Field Name],0))=FALSE,"No Match","Match") -> Match | AQ18: =IF(AND(Table182[[#This Row],[Exists already? (ID)]]="No Match",Table182[[#This Row],[Exists already (Name)]]="No Match"),"No Match",IF(AND(Table182[[#This Row],[Exists already? (ID)]]="Match",Table182[[#This Row],[Exists already (Name)]]="Match"),"Double Match","One Match")) -> One Match | AR18: Added
A19: L1 - Strategy Def | B19: Matt | C19: L1: Desired Business Outcomes and Business Case | D19: Initial Light Business Case | F19: Business Finance | G19: L1 | H19: Drive018 | M19: Initial Net Recurring Benefits ($, annualized)-Total | P19: replace L1 with Initial; Follow up with finance to update definition; decide editability after L0/L1 | Q19: Yes | R19: Yes | S19: 1044 | T19: 1044 | U19: 1044 | AC19: Calculated | AD19: Currency | AH19: Net Recurring Benefits = CY28 Exit Rate, Annualized. Auto-calculation of L1 Hard and Soft Benefits. | AI19: Opt. | AM19: Yes | AO19: =IF(ISNUMBER(_xlfn.XMATCH(Table182[[#This Row],[DEV SB ID]],Platinum_Config[Target DEV SB ID],0))=FALSE,"No Match","Match") -> Match | AP19: =IF(ISNUMBER(_xlfn.XMATCH(Table182[[#This Row],[Target Field Name]],Platinum_Config[Target Field Name],0))=FALSE,"No Match","Match") -> Match | AQ19: =IF(AND(Table182[[#This Row],[Exists already? (ID)]]="No Match",Table182[[#This Row],[Exists already (Name)]]="No Match"),"No Match",IF(AND(Table182[[#This Row],[Exists already? (ID)]]="Match",Table182[[#This Row],[Exists already (Name)]]="Match"),"Double Match","One Match")) -> Double Match | AR19: Added
A20: L1 - Strategy Def | B20: Matt | C20: L1: Desired Business Outcomes and Business Case | D20: Initial Light Business Case | F20: Business Finance | G20: L1 | H20: Drive019 | M20: Initial One-time Benefit ($) | P20: replace L1 with Initial; Follow up with finance to update definition; decide editability after L0/L1 | Q20: Yes | R20: Yes | S20: fdx_l1_otb_total | T20: fdx_l1_otb_total | U20: fdx_l1_otb_total | AC20: Field | AD20: Currency | AH20: Total one-time benefits with a direct impact to the P&L | AI20: Opt. | AO20: =IF(ISNUMBER(_xlfn.XMATCH(Table182[[#This Row],[DEV SB ID]],Platinum_Config[Target DEV SB ID],0))=FALSE,"No Match","Match") -> Match | AP20: =IF(ISNUMBER(_xlfn.XMATCH(Table182[[#This Row],[Target Field Name]],Platinum_Config[Target Field Name],0))=FALSE,"No Match","Match") -> Match | AQ20: =IF(AND(Table182[[#This Row],[Exists already? (ID)]]="No Match",Table182[[#This Row],[Exists already (Name)]]="No Match"),"No Match",IF(AND(Table182[[#This Row],[Exists already? (ID)]]="Match",Table182[[#This Row],[Exists already (Name)]]="Match"),"Double Match","One Match")) -> Double Match | AR20: Added
A21: L1 - Strategy Def | B21: Matt | C21: L1: Desired Business Outcomes and Business Case | D21: Initial Light Business Case | F21: Business Finance | G21: L1 | H21: Drive020 | M21: Key Assumptions Made in Quantifying Impact | P21: replace L1 with Initial; Follow up with finance to update definition; decide editability after L0/L1 | Q21: Yes | R21: Yes | S21: fdx_calc_explan | T21: fdx_calc_explan | U21: fdx_calc_explan | AC21: Field | AD21: Text | AH21: Rationale behind the calculations of value and costs. | AI21: Opt. | AO21: =IF(ISNUMBER(_xlfn.XMATCH(Table182[[#This Row],[DEV SB ID]],Platinum_Config[Target DEV SB ID],0))=FALSE,"No Match","Match") -> No Match | AP21: =IF(ISNUMBER(_xlfn.XMATCH(Table182[[#This Row],[Target Field Name]],Platinum_Config[Target Field Name],0))=FALSE,"No Match","Match") -> Match | AQ21: =IF(AND(Table182[[#This Row],[Exists already? (ID)]]="No Match",Table182[[#This Row],[Exists already (Name)]]="No Match"),"No Match",IF(AND(Table182[[#This Row],[Exists already? (ID)]]="Match",Table182[[#This Row],[Exists already (Name)]]="Match"),"Double Match","One Match")) -> One Match | AR21: Ignore
